Workbook

Sheet 종합
C2: AI 테스트 종합
B4: # | C4: 개요 | D4: deepseekr1 | E4: Qwen 2.5max | F4: o3mini high | G4: Tulu3 | H4: deepseekr1 | I4: deepseekr1 | J4: gemini2flash | K4: gemini2pro | L4: llama3.3 | M4: grok 2 | N4: Mistral | O4: kimi 1.5 | P4: kimi 1.5 | Q4: clovaX | R4: Exaone | S4: Exaone | T4: Luxia 2 | U4: Luxia 2 | V4: grok 3 | W4: grok 3 | X4: Claude 3.5s | Y4: Claude3.7s | Z4: Qwen2.5Max | AA4: kanana | AB4: deepseekr1 | AC4: ChatGPT4.5 | AD4: Mercury coder | AE4: Solar pro | AF4: QwQ-32b | AG4: Phi4 | AH4: Gemma3 | AI4: Gemma3 | AJ4: Gemma3 | AK4: Gemma3 | AL4: Command A | AM4: Reka Flash 3 | AN4: Ernie x1 | AO4: Hunyuan T1 | AP4: Deepseekv30324 | AQ4: gemini 2.5 pro exp. | AR4: Llama4 scout | AS4: Llama4 Maverick | AT4: Quasar Alpha | AU4: Cogito v1 | AV4: Cogito v1 | AW4: Zyphra ZR1 | AX4: Optimus Alpha | AY4: Deepcoder | AZ4: Exaone deep | BA4: Exaone deep | BB4: GPT 4.1 mini | BC4: GPT 4.1 | BD4: o3 | BE4: o4 mini | BF4: o4 mini high | BG4: gemini 2.5 Flash | BH4: Gemma 3 QAT | BI4: Grok 3 mini | BJ4: BitNet b1.58 | BK4: BitNet b1.58 | BL4: ClovaX seed bf16 | BM4: ClovaX seed Q8 | BN4: Ernie X1 Turbo | BO4: Ernie 4.5 Turbo | BP4: DeepCoder | BQ4: Qwen3 235A22B | BR4: Qwen3 30A3B | BS4: Qwen3 32 | BT4: Qwen3 14 | BU4: Qwen3 8 | BV4: 정답률
C5: size | D5: 70 | G5: 405 | H5: 8 | I5: 70 | L5: 70 | R5: 7.8 | S5: 7.8 | T5: 32 | U5: 8 | AA5: 2.1 | AB5: 1.5 | AE5: 22 | AF5: 32 | AG5: 14 | AH5: 27 | AI5: 12 | AJ5: 4 | AK5: 1 | AL5: 111 | AM5: 21 | AP5: 685 | AR5: 109 | AS5: 400 | AU5: 8 | AV5: 14 | AW5: 1.5 | AY5: 1.5 | AZ5: 2.4 | BA5: 7.8 | BH5: 12 | BJ5: 2 | BK5: 2 | BL5: 1.5 | BM5: 1.5 | BP5: 14 | BQ5: 235 | BR5: 30 | BS5: 32 | BT5: 14 | BU5: 8
C6: Evironment | D6: groq | H6: Lmstudio | I6: Wrtn | L6: cerebras | N6: le chat | R6: H/F | S6: OpenWebUI | V6: lmarena | W6: beta | AA6: OpenWebUI | AB6: OpenWebUI | AG6: github | AH6: AIstudio | AI6: OpenWebUI | AJ6: OpenWebUI | AK6: OpenWebUI | AP6: OpenRouter | AR6: Groq | AS6: OpenRouter | AT6: OpenRouter | AU6: Ollama | AV6: Ollama | AW6: LMStudio | AX6: OpenRouter | AY6: LMStudio | AZ6: Ollama | BA6: Ollama | BB6: Playground | BC6: Playground | BH6: OpenWebUI | BI6: API / JN | BJ6: Azure | BK6: WSL | BL6: Jupyter NB | BM6: OpenWebUI | BP6: OpenRouter | BS6: OpenRouter | BT6: OpenRouter | BU6: OpenRouter
C7: optoins (R: reasoning) | D7: R | F7: R | H7: R | I7: R | J7: R | P7: R | W7: R | Y7: R | Z7: R | AB7: R | AF7: R | AM7: R | AN7: R | AO7: R | AQ7: R | AW7: R | AY7: R | AZ7: R | BA7: R | BD7: R | BE7: R | BF7: R | BG7: R | BI7: R | BN7: R | BP7: R | BQ7: R | BR7: R | BS7: R | BT7: R | BU7: R
BN8: 2025.4.25 | BO8: 2025.4.25 | BP8: 2025.4.27 | BQ8: 2025.4.29 | BR8: 2025.4.29 | BS8: 2025.4.30 | BT8: 2025.4.30 | BU8: 2025.4.30
B9: 1 | C9: AABABCABCD 다음은? | D9: 1 | E9: 1 | F9: 1 | G9: 1 | H9: 0 | I9: 1 | J9: 0 | K9: 1 | L9: 0 | M9: 0 | N9: 1 | O9: 1 | P9: 1 | Q9: 0 | R9: 0 | S9: 0 | T9: 0 | U9: 0 | V9: 1 | W9: 1 | X9: 1 | Y9: 1 | Z9: 1 | AA9: 0 | AB9: 0 | AC9: 1 | AD9: 0 | AE9: 0 | AF9: 1 | AG9: 1 | AH9: 1 | AI9: 0 | AJ9: 0 | AK9: 0 | AL9: 0 | AM9: 0 | AN9: 1 | AO9: 0 | AP9: 1 | AQ9: 1 | AR9: 0 | AS9: 1 | AT9: 1 | AU9: 0 | AV9: 1 | AW9: 0 | AX9: 1 | AY9: 0 | AZ9: 0 | BA9: 0 | BB9: 1 | BC9: 1 | BD9: 1 | BE9: 1 | BF9: 1 | BG9: 1 | BH9: 0 | BI9: 1 | BJ9: 0 | BK9: 0 | BL9: 0 | BM9: 0 | BN9: 1 | BO9: 0 | BP9: 0 | BQ9: 1 | BR9: 1 | BS9: 1 | BT9: 1 | BU9: 0 | BV9: =IFERROR(__xludf.DUMMYFUNCTION("AVERAGE(FILTER(D9:BR9, D9:BR9 <> """"))"),0.522388059701492) -> 0.52238806
B10: 2 | C10: 어떤 수에 5를더하면 2배보다 3작음. 어떤 수는? | D10: 1 | E10: 1 | F10: 1 | G10: 1 | H10: 1 | I10: 1 | J10: 1 | K10: 1 | L10: 1 | M10: 1 | N10: 1 | O10: 1 | P10: 1 | Q10: 1 | R10: 1 | S10: 1 | T10: 1 | U10: 1 | V10: 1 | W10: 1 | X10: 1 | Y10: 1 | Z10: 1 | AA10: 1 | AB10: 1 | AC10: 1 | AD10: 1 | AE10: 1 | AF10: 1 | AG10: 1 | AH10: 1 | AI10: 1 | AJ10: 1 | AK10: 0 | AL10: 1 | AM10: 1 | AN10: 1 | AO10: 1 | AP10: 1 | AQ10: 1 | AR10: 1 | AS10: 1 | AT10: 1 | AU10: 1 | AV10: 1 | AW10: 1 | AX10: 1 | AY10: 1 | AZ10: 1 | BA10: 1 | BB10: 1 | BC10: 1 | BD10: 1 | BE10: 1 | BF10: 1 | BG10: 1 | BH10: 1 | BI10: 1 | BJ10: 0 | BK10: 1 | BL10: 1 | BM10: 1 | BN10: 1 | BO10: 1 | BP10: 1 | BQ10: 1 | BR10: 1 | BS10: 1 | BT10: 1 | BU10: 1 | BV10: =IFERROR(__xludf.DUMMYFUNCTION("AVERAGE(FILTER(D10:BR10, D10:BR10 <> """"))"),0.970149253731343) -> 0.97014925
B11: 3 | C11: 패턴. 빨강,파랑,노랑,초록,보라. 57번째 색은? | D11: 1 | E11: 1 | F11: 1 | G11: 1 | H11: 1 | I11: 1 | J11: 1 | K11: 1 | L11: 1 | M11: 1 | N11: 1 | O11: 1 | P11: 1 | Q11: 1 | R11: 1 | S11: 1 | T11: 1 | U11: 1 | V11: 1 | W11: 1 | X11: 1 | Y11: 1 | Z11: 1 | AA11: 0 | AB11: 1 | AC11: 1 | AD11: 1 | AE11: 1 | AF11: 1 | AG11: 1 | AH11: 1 | AI11: 1 | AJ11: 0 | AK11: 0 | AL11: 1 | AM11: 1 | AN11: 1 | AO11: 1 | AP11: 1 | AQ11: 1 | AR11: 1 | AS11: 1 | AT11: 1 | AU11: 1 | AV11: 1 | AW11: 1 | AX11: 1 | AY11: 1 | AZ11: 1 | BA11: 1 | BB11: 1 | BC11: 1 | BD11: 1 | BE11: 1 | BF11: 1 | BG11: 1 | BH11: 1 | BI11: 1 | BJ11: 1 | BK11: 1 | BL11: 1 | BM11: 1 | BN11: 1 | BO11: 1 | BP11: 1 | BQ11: 1 | BR11: 1 | BS11: 1 | BT11: 1 | BU11: 1 | BV11: =IFERROR(__xludf.DUMMYFUNCTION("AVERAGE(FILTER(D11:BR11, D11:BR11 <> """"))"),0.955223880597014) -> 0.95522388
B12: 4 | C12: A가 B보다 먼저,C보다 늦게,D는 E보다 먼저,B보다 늦게.전체순서는? | D12: 1 | E12: 1 | F12: 1 | G12: 1 | H12: 1 | I12: 1 | J12: 1 | K12: 1 | L12: 1 | M12: 0 | N12: 1 | O12: 1 | P12: 1 | Q12: 0 | R12: 0 | S12: 1 | T12: 0 | U12: 0 | V12: 1 | W12: 1 | X12: 1 | Y12: 1 | Z12: 1 | AA12: 0 | AB12: 0 | AC12: 1 | AD12: 0 | AE12: 0 | AF12: 1 | AG12: 0 | AH12: 1 | AI12: 0 | AJ12: 0 | AK12: 0 | AL12: 1 | AM12: 1 | AN12: 1 | AO12: 1 | AP12: 1 | AQ12: 1 | AR12: 1 | AS12: 1 | AT12: 0 | AU12: 1 | AV12: 1 | AW12: 1 | AX12: 0 | AY12: 1 | AZ12: 0 | BA12: 1 | BB12: 0 | BC12: 1 | BD12: 1 | BE12: 1 | BF12: 1 | BG12: 1 | BH12: 1 | BI12: 1 | BJ12: 0 | BK12: 1 | BL12: 0 | BM12: 0 | BN12: 1 | BO12: 0 | BP12: 0 | BQ12: 1 | BR12: 1 | BS12: 1 | BT12: 1 | BU12: 1 | BV12: =IFERROR(__xludf.DUMMYFUNCTION("AVERAGE(FILTER(D12:BR12, D12:BR12 <> """"))"),0.671641791044776) -> 0.67164179
B13: 5 | C13: 검은모자x2개, 흰모자 x2개. 3명이 앞만 볼 수 있을 때. 맨 앞사람 모자색? | D13: 1 | E13: 1 | F13: 1 | G13: 1 | H13: 1 | I13: 1 | J13: 1 | K13: 1 | L13: 1 | M13: 1 | N13: 1 | O13: 1 | P13: 1 | Q13: 1 | R13: 1 | S13: 0 | T13: 1 | U13: 0 | V13: 1 | W13: 1 | X13: 1 | Y13: 1 | Z13: 1 | AA13: 0 | AB13: 1 | AC13: 1 | AD13: 1 | AE13: 0 | AF13: 1 | AG13: 0 | AH13: 1 | AI13: 1 | AJ13: 1 | AK13: 0 | AL13: 0 | AM13: 1 | AN13: 1 | AO13: 1 | AP13: 1 | AQ13: 1 | AR13: 1 | AS13: 1 | AT13: 1 | AU13: 0 | AV13: 0 | AW13: 1 | AX13: 1 | AY13: 0 | AZ13: 0 | BA13: 0 | BB13: 1 | BC13: 0 | BD13: 1 | BE13: 1 | BF13: 1 | BG13: 1 | BH13: 1 | BI13: 1 | BJ13: 0 | BK13: 1 | BL13: 0 | BM13: 0 | BN13: 1 | BO13: 1 | BP13: 1 | BQ13: 1 | BR13: 1 | BS13: 1 | BT13: 1 | BU13: 1 | BV13: =IFERROR(__xludf.DUMMYFUNCTION("AVERAGE(FILTER(D13:BR13, D13:BR13 <> """"))"),0.761194029850746) -> 0.76119403
B14: 6 | C14: 26개 동전 중 1개 가짜 동전. 최소 몇 번의 양팔 저울질로 가짜 구분? | D14: 1 | E14: 1 | F14: 1 | G14: 1 | H14: 1 | I14: 1 | J14: 1 | K14: 1 | L14: 1 | M14: 1 | N14: 0 | O14: 1 | P14: 1 | Q14: 0 | R14: 1 | S14: 0 | T14: 0 | U14: 0 | V14: 0 | W14: 1 | X14: 1 | Y14: 1 | Z14: 1 | AA14: 0 | AB14: 1 | AC14: 1 | AD14: 1 | AE14: 1 | AF14: 1 | AG14: 0 | AH14: 0 | AI14: 0 | AJ14: 0 | AK14: 0 | AL14: 1 | AM14: 0 | AN14: 1 | AO14: 1 | AP14: 1 | AQ14: 1 | AR14: 1 | AS14: 1 | AT14: 1 | AU14: 0 | AV14: 0 | AW14: 1 | AX14: 1 | AY14: 1 | AZ14: 0 | BA14: 0 | BB14: 1 | BC14: 1 | BD14: 1 | BE14: 1 | BF14: 1 | BG14: 1 | BH14: 0 | BI14: 1 | BJ14: 0 | BK14: 0 | BL14: 0 | BM14: 0 | BN14: 1 | BO14: 1 | BP14: 1 | BQ14: 1 | BR14: 1 | BS14: 1 | BT14: 1 | BU14: 1 | BV14: =IFERROR(__xludf.DUMMYFUNCTION("AVERAGE(FILTER(D14:BR14, D14:BR14 <> """"))"),0.671641791044776) -> 0.67164179
B15: 7 | C15: 현재 아버지 나이가 아들의 4배,5년 전에는 아들의 5배,아빠 나이는? | D15: 1 | E15: 1 | F15: 1 | G15: 1 | H15: 1 | I15: 1 | J15: 1 | K15: 1 | L15: 1 | M15: 1 | N15: 1 | O15: 1 | P15: 1 | Q15: 1 | R15: 1 | S15: 1 | T15: 1 | U15: 0 | V15: 1 | W15: 1 | X15: 1 | Y15: 1 | Z15: 1 | AA15: 0 | AB15: 0 | AC15: 1 | AD15: 1 | AE15: 0 | AF15: 1 | AG15: 1 | AH15: 1 | AI15: 1 | AJ15: 1 | AK15: 0 | AL15: 1 | AM15: 1 | AN15: 1 | AO15: 1 | AP15: 1 | AQ15: 1 | AR15: 1 | AS15: 1 | AT15: 1 | AU15: 0 | AV15: 1 | AW15: 1 | AX15: 1 | AY15: 1 | AZ15: 0 | BA15: 1 | BB15: 1 | BC15: 1 | BD15: 1 | BE15: 1 | BF15: 1 | BG15: 1 | BH15: 1 | BI15: 1 | BJ15: 1 | BK15: 1 | BL15: 0 | BM15: 1 | BN15: 1 | BO15: 1 | BP15: 1 | BQ15: 1 | BR15: 1 | BS15: 1 | BT15: 1 | BU15: 1 | BV15: =IFERROR(__xludf.DUMMYFUNCTION("AVERAGE(FILTER(D15:BR15, D15:BR15 <> """"))"),0.880597014925373) -> 0.88059701
B16: 8 | C16: 세명의 용의자 중1명은 진실 2명은 거짓말함. 범인은? | D16: 0 | E16: 0 | F16: 1 | G16: 0 | H16: 0 | I16: 1 | J16: 1 | K16: 1 | L16: 0 | M16: 0 | N16: 1 | O16: 0 | P16: 1 | Q16: 0 | R16: 0 | S16: 0 | T16: 0 | U16: 0 | V16: 1 | W16: 1 | X16: 0 | Y16: 1 | Z16: 1 | AA16: 1 | AB16: 1 | AC16: 1 | AD16: 1 | AE16: 1 | AF16: 1 | AG16: 1 | AH16: 1 | AI16: 0 | AJ16: 0 | AK16: 0 | AL16: 1 | AM16: 0 | AN16: 1 | AO16: 1 | AP16: 1 | AQ16: 1 | AR16: 1 | AS16: 0 | AT16: 1 | AU16: 1 | AV16: 0 | AW16: 1 | AX16: 1 | AY16: 1 | AZ16: 0 | BA16: 1 | BB16: 1 | BC16: 1 | BD16: 1 | BE16: 1 | BF16: 1 | BG16: 1 | BH16: 1 | BI16: 1 | BJ16: 0 | BK16: 0 | BL16: 0 | BM16: 0 | BN16: 1 | BO16: 1 | BP16: 1 | BQ16: 1 | BR16: 1 | BS16: 1 | BT16: 1 | BU16: 1 | BV16: =IFERROR(__xludf.DUMMYFUNCTION("AVERAGE(FILTER(D16:BR16, D16:BR16 <> """"))"),0.641791044776119) -> 0.64179104
B17: 9 | C17: 8면체 주사위 2개 던질 때, 두 수의 곱이 합보다 큰 확률은? | E17: 1 | F17: 1 | G17: 0 | H17: 1 | I17: 1 | J17: 1 | K17: 0 | L17: 0 | M17: 0 | N17: 1 | O17: 1 | P17: 1 | Q17: 0 | R17: 0 | S17: 0 | T17: 0 | U17: 0 | V17: 1 | W17: 1 | X17: 1 | Y17: 1 | Z17: 1 | AA17: 0 | AB17: 0 | AC17: 1 | AD17: 0 | AE17: 0 | AF17: 1 | AG17: 1 | AH17: 1 | AI17: 1 | AJ17: 0 | AK17: 0 | AL17: 0 | AM17: 1 | AN17: 1 | AO17: 1 | AP17: 1 | AQ17: 1 | AR17: 0 | AS17: 0 | AT17: 1 | AU17: 0 | AV17: 0 | AW17: 1 | AX17: 1 | AY17: 0 | AZ17: 0 | BA17: 0 | BB17: 1 | BC17: 1 | BD17: 1 | BE17: 1 | BF17: 1 | BG17: 1 | BH17: 0 | BI17: 1 | BJ17: 0 | BK17: 0 | BL17: 0 | BM17: 0 | BN17: 1 | BO17: 1 | BP17: 1 | BQ17: 1 | BR17: 1 | BS17: 1 | BT17: 1 | BU17: 1 | BV17: =IFERROR(__xludf.DUMMYFUNCTION("AVERAGE(FILTER(D17:BR17, D17:BR17 <> """"))"),0.575757575757575) -> 0.57575758
B18: 10 | C18: 엔지니어링: USD 설계방법으로 필요 철근량 구하기. | F18: 1 | G18: 1 | H18: 0 | I18: 1 | J18: 1 | K18: 1 | L18: 0 | M18: 0 | N18: 1 | O18: 0 | P18: 0 | Q18: 0 | R18: 0 | S18: 0 | T18: 0 | U18: 0 | V18: 1 | W18: 1 | X18: 1 | Y18: 1 | Z18: 0 | AA18: 0 | AB18: 0 | AC18: 1 | AD18: 0 | AE18: 0 | AF18: 0 | AG18: 0 | AH18: 0 | AI18: 0 | AJ18: 0 | AK18: 0 | AL18: 0 | AM18: 0 | AN18: 0 | AO18: 1 | AP18: 0 | AQ18: 1 | AR18: 0 | AS18: 1 | AT18: 1 | AU18: 0 | AV18: 0 | AW18: 0 | AX18: 0 | AY18: 0 | AZ18: 0 | BA18: 0 | BB18: 1 | BC18: 1 | BD18: 1 | BE18: 1 | BF18: 0 | BG18: 1 | BH18: 0 | BI18: 1 | BJ18: 0 | BK18: 0 | BL18: 0 | BM18: 0 | BN18: 1 | BO18: 0 | BP18: 0 | BQ18: 1 | BR18: 1 | BS18: 1 | BT18: 1 | BU18: 1 | BV18: =IFERROR(__xludf.DUMMYFUNCTION("AVERAGE(FILTER(D18:BR18, D18:BR18 <> """"))"),0.369230769230769) -> 0.36923077
B19: 11 | C19: 코딩: 2차방정식 a,b,c 입력 받아 근 구하고 그래프 그리는 웹앱 | E19: 0 | F19: 1 | G19: 0 | H19: 0 | I19: 1 | J19: 0 | K19: 1 | L19: 0 | M19: 0 | N19: 0 | O19: 0 | P19: 0 | Q19: 0 | R19: 0 | S19: 0 | T19: 0 | U19: 0 | V19: 1 | W19: 1 | X19: 1 | Y19: 1 | Z19: 0 | AA19: 0 | AB19: 0 | AC19: 0 | AD19: 0 | AE19: 0 | AF19: 0 | AG19: 0 | AH19: 0 | AI19: 0 | AJ19: 0 | AK19: 0 | AL19: 0 | AM19: 0 | AN19: 0 | AO19: 0 | AP19: 0 | AQ19: 1 | AR19: 0 | AS19: 1 | AT19: 1 | AU19: 0 | AV19: 0 | AW19: 0 | AX19: 0 | AY19: 0 | AZ19: 0 | BA19: 0 | BB19: 1 | BC19: 1 | BD19: 1 | BE19: 0 | BF19: 0 | BG19: 0 | BH19: 0 | BI19: 1 | BJ19: 0 | BK19: 0 | BL19: 0 | BM19: 0 | BN19: 0 | BO19: 0 | BP19: 0 | BQ19: 1 | BR19: 0 | BS19: 0 | BT19: 0 | BU19: 0 | BV19: =IFERROR(__xludf.DUMMYFUNCTION("AVERAGE(FILTER(D19:BR19, D19:BR19 <> """"))"),0.227272727272727) -> 0.22727273
B20: 12 | C20: 코딩: I-Beam 제원 입력받아 그리기 및 단면적계산 | G20: 1 | H20: 0 | I20: 1 | J20: 0 | K20: 1 | L20: 0 | M20: 1 | N20: 0 | O20: 0 | P20: 1 | Q20: 0 | R20: 0 | S20: 0 | T20: 0 | U20: 0 | V20: 1 | W20: 1 | X20: 1 | Y20: 1 | Z20: 1 | AA20: 0 | AB20: 0 | AC20: 1 | AD20: 0 | AE20: 0 | AF20: 0 | AG20: 1 | AH20: 0 | AI20: 0 | AJ20: 0 | AK20: 0 | AL20: 0 | AM20: 0 | AN20: 1 | AO20: 0 | AP20: 1 | AQ20: 1 | AR20: 0 | AS20: 1 | AT20: 1 | AU20: 0 | AV20: 0 | AW20: 0 | AX20: 1 | AY20: 0 | AZ20: 0 | BA20: 0 | BB20: 1 | BC20: 0 | BD20: 1 | BE20: 1 | BF20: 1 | BG20: 1 | BH20: 0 | BI20: 0 | BJ20: 0 | BK20: 0 | BL20: 0 | BM20: 0 | BN20: 0 | BO20: 1 | BP20: 1 | BQ20: 1 | BR20: 1 | BS20: 0 | BT20: 0 | BU20: 1 | BV20: =IFERROR(__xludf.DUMMYFUNCTION("AVERAGE(FILTER(D20:BR20, D20:BR20 <> """"))"),0.421875) -> 0.421875
C21: 점수 | D21: =IFERROR(__xludf.DUMMYFUNCTION("AVERAGE(FILTER(D9:D20, D9:D20 <> """"))"),0.875) -> 0.875 | E21: =IFERROR(__xludf.DUMMYFUNCTION("AVERAGE(FILTER(E9:E20, E9:E20 <> """"))"),0.8) -> 0.8 | F21: =IFERROR(__xludf.DUMMYFUNCTION("AVERAGE(FILTER(F9:F20, F9:F20 <> """"))"),1) -> 1 | G21: =IFERROR(__xludf.DUMMYFUNCTION("AVERAGE(FILTER(G9:G20, G9:G20 <> """"))"),0.75) -> 0.75 | H21: =IFERROR(__xludf.DUMMYFUNCTION("AVERAGE(FILTER(H9:H20, H9:H20 <> """"))"),0.583333333333333) -> 0.58333333 | I21: =IFERROR(__xludf.DUMMYFUNCTION("AVERAGE(FILTER(I9:I20, I9:I20 <> """"))"),1) -> 1 | J21: =IFERROR(__xludf.DUMMYFUNCTION("AVERAGE(FILTER(J9:J20, J9:J20 <> """"))"),0.75) -> 0.75 | K21: =IFERROR(__xludf.DUMMYFUNCTION("AVERAGE(FILTER(K9:K20, K9:K20 <> """"))"),0.916666666666666) -> 0.91666667 | L21: =IFERROR(__xludf.DUMMYFUNCTION("AVERAGE(FILTER(L9:L20, L9:L20 <> """"))"),0.5) -> 0.5 | M21: =IFERROR(__xludf.DUMMYFUNCTION("AVERAGE(FILTER(M9:M20, M9:M20 <> """"))"),0.5) -> 0.5 | N21: =IFERROR(__xludf.DUMMYFUNCTION("AVERAGE(FILTER(N9:N20, N9:N20 <> """"))"),0.75) -> 0.75 | O21: =IFERROR(__xludf.DUMMYFUNCTION("AVERAGE(FILTER(O9:O20, O9:O20 <> """"))"),0.666666666666666) -> 0.66666667 | P21: =IFERROR(__xludf.DUMMYFUNCTION("AVERAGE(FILTER(P9:P20, P9:P20 <> """"))"),0.833333333333333) -> 0.83333333 | Q21: =IFERROR(__xludf.DUMMYFUNCTION("AVERAGE(FILTER(Q9:Q20, Q9:Q20 <> """"))"),0.333333333333333) -> 0.33333333 | R21: =IFERROR(__xludf.DUMMYFUNCTION("AVERAGE(FILTER(R9:R20, R9:R20 <> """"))"),0.416666666666666) -> 0.41666667 | S21: =IFERROR(__xludf.DUMMYFUNCTION("AVERAGE(FILTER(S9:S20, S9:S20 <> """"))"),0.333333333333333) -> 0.33333333 | T21: =IFERROR(__xludf.DUMMYFUNCTION("AVERAGE(FILTER(T9:T20, T9:T20 <> """"))"),0.333333333333333) -> 0.33333333 | U21: =IFERROR(__xludf.DUMMYFUNCTION("AVERAGE(FILTER(U9:U20, U9:U20 <> """"))"),0.166666666666666) -> 0.16666667 | V21: =IFERROR(__xludf.DUMMYFUNCTION("AVERAGE(FILTER(V9:V20, V9:V20 <> """"))"),0.916666666666666) -> 0.91666667 | W21: =IFERROR(__xludf.DUMMYFUNCTION("AVERAGE(FILTER(W9:W20, W9:W20 <> """"))"),1) -> 1 | X21: =IFERROR(__xludf.DUMMYFUNCTION("AVERAGE(FILTER(X9:X20, X9:X20 <> """"))"),0.916666666666666) -> 0.91666667 | Y21: =IFERROR(__xludf.DUMMYFUNCTION("AVERAGE(FILTER(Y9:Y20, Y9:Y20 <> """"))"),1) -> 1 | Z21: =IFERROR(__xludf.DUMMYFUNCTION("AVERAGE(FILTER(Z9:Z20, Z9:Z20 <> """"))"),0.833333333333333) -> 0.83333333 | AA21: =IFERROR(__xludf.DUMMYFUNCTION("AVERAGE(FILTER(AA9:AA20, AA9:AA20 <> """"))"),0.166666666666666) -> 0.16666667 | AB21: =IFERROR(__xludf.DUMMYFUNCTION("AVERAGE(FILTER(AB9:AB20, AB9:AB20 <> """"))"),0.416666666666666) -> 0.41666667 | AC21: =IFERROR(__xludf.DUMMYFUNCTION("AVERAGE(FILTER(AC9:AC20, AC9:AC20 <> """"))"),0.916666666666666) -> 0.91666667 | AD21: =IFERROR(__xludf.DUMMYFUNCTION("AVERAGE(FILTER(AD9:AD20, AD9:AD20 <> """"))"),0.5) -> 0.5 | AE21: =IFERROR(__xludf.DUMMYFUNCTION("AVERAGE(FILTER(AE9:AE20, AE9:AE20 <> """"))"),0.333333333333333) -> 0.33333333 | AF21: =IFERROR(__xludf.DUMMYFUNCTION("AVERAGE(FILTER(AF9:AF20, AF9:AF20 <> """"))"),0.75) -> 0.75 | AG21: =IFERROR(__xludf.DUMMYFUNCTION("AVERAGE(FILTER(AG9:AG20, AG9:AG20 <> """"))"),0.583333333333333) -> 0.58333333 | AH21: =IFERROR(__xludf.DUMMYFUNCTION("AVERAGE(FILTER(AH9:AH20, AH9:AH20 <> """"))"),0.666666666666666) -> 0.66666667 | AI21: =IFERROR(__xludf.DUMMYFUNCTION("AVERAGE(FILTER(AI9:AI20, AI9:AI20 <> """"))"),0.416666666666666) -> 0.41666667 | AJ21: =IFERROR(__xludf.DUMMYFUNCTION("AVERAGE(FILTER(AJ9:AJ20, AJ9:AJ20 <> """"))"),0.25) -> 0.25 | AK21: =IFERROR(__xludf.DUMMYFUNCTION("AVERAGE(FILTER(AK9:AK20, AK9:AK20 <> """"))"),0) -> 0 | AL21: =IFERROR(__xludf.DUMMYFUNCTION("AVERAGE(FILTER(AL9:AL20, AL9:AL20 <> """"))"),0.5) -> 0.5 | AM21: =IFERROR(__xludf.DUMMYFUNCTION("AVERAGE(FILTER(AM9:AM20, AM9:AM20 <> """"))"),0.5) -> 0.5 | AN21: =IFERROR(__xludf.DUMMYFUNCTION("AVERAGE(FILTER(AN9:AN20, AN9:AN20 <> """"))"),0.833333333333333) -> 0.83333333 | AO21: =IFERROR(__xludf.DUMMYFUNCTION("AVERAGE(FILTER(AO9:AO20, AO9:AO20 <> """"))"),0.75) -> 0.75 | AP21: =IFERROR(__xludf.DUMMYFUNCTION("AVERAGE(FILTER(AP9:AP20, AP9:AP20 <> """"))"),0.833333333333333) -> 0.83333333 | AQ21: =IFERROR(__xludf.DUMMYFUNCTION("AVERAGE(FILTER(AQ9:AQ20, AQ9:AQ20 <> """"))"),1) -> 1 | AR21: =IFERROR(__xludf.DUMMYFUNCTION("AVERAGE(FILTER(AR9:AR20, AR9:AR20 <> """"))"),0.583333333333333) -> 0.58333333 | AS21: =IFERROR(__xludf.DUMMYFUNCTION("AVERAGE(FILTER(AS9:AS20, AS9:AS20 <> """"))"),0.833333333333333) -> 0.83333333 | AT21: =IFERROR(__xludf.DUMMYFUNCTION("AVERAGE(FILTER(AT9:AT20, AT9:AT20 <> """"))"),0.916666666666666) -> 0.91666667 | AU21: =IFERROR(__xludf.DUMMYFUNCTION("AVERAGE(FILTER(AU9:AU20, AU9:AU20 <> """"))"),0.333333333333333) -> 0.33333333 | AV21: =IFERROR(__xludf.DUMMYFUNCTION("AVERAGE(FILTER(AV9:AV20, AV9:AV20 <> """"))"),0.416666666666666) -> 0.41666667 | AW21: =IFERROR(__xludf.DUMMYFUNCTION("AVERAGE(FILTER(AW9:AW20, AW9:AW20 <> """"))"),0.666666666666666) -> 0.66666667 | AX21: =IFERROR(__xludf.DUMMYFUNCTION("AVERAGE(FILTER(AX9:AX20, AX9:AX20 <> """"))"),0.75) -> 0.75 | AY21: =IFERROR(__xludf.DUMMYFUNCTION("AVERAGE(FILTER(AY9:AY20, AY9:AY20 <> """"))"),0.5) -> 0.5 | AZ21: =IFERROR(__xludf.DUMMYFUNCTION("AVERAGE(FILTER(AZ9:AZ20, AZ9:AZ20 <> """"))"),0.166666666666666) -> 0.16666667 | BA21: =IFERROR(__xludf.DUMMYFUNCTION("AVERAGE(FILTER(BA9:BA20, BA9:BA20 <> """"))"),0.416666666666666) -> 0.41666667 | BB21: =IFERROR(__xludf.DUMMYFUNCTION("AVERAGE(FILTER(BB9:BB20, BB9:BB20 <> """"))"),0.916666666666666) -> 0.91666667 | BC21: =IFERROR(__xludf.DUMMYFUNCTION("AVERAGE(FILTER(BC9:BC20, BC9:BC20 <> """"))"),0.833333333333333) -> 0.83333333 | BD21: =IFERROR(__xludf.DUMMYFUNCTION("AVERAGE(FILTER(BD9:BD20, BD9:BD20 <> """"))"),1) -> 1 | BE21: =IFERROR(__xludf.DUMMYFUNCTION("AVERAGE(FILTER(BE9:BE20, BE9:BE20 <> """"))"),0.916666666666666) -> 0.91666667 | BF21: =IFERROR(__xludf.DUMMYFUNCTION("AVERAGE(FILTER(BF9:BF20, BF9:BF20 <> """"))"),0.833333333333333) -> 0.83333333 | BG21: =IFERROR(__xludf.DUMMYFUNCTION("AVERAGE(FILTER(BG9:BG20, BG9:BG20 <> """"))"),0.916666666666666) -> 0.91666667 | BH21: =IFERROR(__xludf.DUMMYFUNCTION("AVERAGE(FILTER(BH9:BH20, BH9:BH20 <> """"))"),0.5) -> 0.5 | BI21: =IFERROR(__xludf.DUMMYFUNCTION("AVERAGE(FILTER(BI9:BI20, BI9:BI20 <> """"))"),0.916666666666666) -> 0.91666667 | BJ21: =IFERROR(__xludf.DUMMYFUNCTION("AVERAGE(FILTER(BJ9:BJ20, BJ9:BJ20 <> """"))"),0.166666666666666) -> 0.16666667 | BK21: =IFERROR(__xludf.DUMMYFUNCTION("AVERAGE(FILTER(BK9:BK20, BK9:BK20 <> """"))"),0.416666666666666) -> 0.41666667 | BL21: =IFERROR(__xludf.DUMMYFUNCTION("AVERAGE(FILTER(BL9:BL20, BL9:BL20 <> """"))"),0.166666666666666) -> 0.16666667 | BM21: =IFERROR(__xludf.DUMMYFUNCTION("AVERAGE(FILTER(BM9:BM20, BM9:BM20 <> """"))"),0.25) -> 0.25 | BN21: =IFERROR(__xludf.DUMMYFUNCTION("AVERAGE(FILTER(BN9:BN20, BN9:BN20 <> """"))"),0.833333333333333) -> 0.83333333 | BO21: =IFERROR(__xludf.DUMMYFUNCTION("AVERAGE(FILTER(BO9:BO20, BO9:BO20 <> """"))"),0.666666666666666) -> 0.66666667 | BP21: =IFERROR(__xludf.DUMMYFUNCTION("AVERAGE(FILTER(BP9:BP20, BP9:BP20 <> """"))"),0.666666666666666) -> 0.66666667 | BQ21: =IFERROR(__xludf.DUMMYFUNCTION("AVERAGE(FILTER(BQ9:BQ20, BQ9:BQ20 <> """"))"),1) -> 1 | BR21: =IFERROR(__xludf.DUMMYFUNCTION("AVERAGE(FILTER(BR9:BR20, BR9:BR20 <> """"))"),0.916666666666666) -> 0.91666667 | BS21: =IFERROR(__xludf.DUMMYFUNCTION("AVERAGE(FILTER(BS9:BS20, BS9:BS20 <> """"))"),0.833333333333333) -> 0.83333333 | BT21: =IFERROR(__xludf.DUMMYFUNCTION("AVERAGE(FILTER(BT9:BT20, BT9:BT20 <> """"))"),0.833333333333333) -> 0.83333333 | BU21: =IFERROR(__xludf.DUMMYFUNCTION("AVERAGE(FILTER(BU9:BU20, BU9:BU20 <> """"))"),0.833333333333333) -> 0.83333333 | BV21: =IFERROR(__xludf.DUMMYFUNCTION("AVERAGE(FILTER(D21:BR21, D21:BR21 <> """"))"),0.643159203980099) -> 0.6431592

Sheet 종합V
B2: Model | C2: size | D2: Env. | E2: R | F2: Point | G2: 1 | H2: 2 | I2: 3 | J2: 4 | K2: 5 | L2: 6 | M2: 7 | N2: 8 | O2: 9 | P2: 10 | Q2: 11 | R2: 12 | S2: Test Date
B3: =종합!BQ4 -> Qwen3 235A22B | C3: =종합!BQ5 -> 235 | E3: =종합!BQ7 -> R | F3: =종합!BQ21 -> 1 | G3: =IF(F3>0/12,1,0) -> 1 | H3: =IF(F3>1/12,1,0) -> 1 | I3: =IF(F3>2/12,1,0) -> 1 | J3: =IF(F3>3/12,1,0) -> 1 | K3: =IF(F3>4/12,1,0) -> 1 | L3: =IF(F3>5/12,1,0) -> 1 | M3: =IF(F3>6/12,1,0) -> 1 | N3: =IF(F3>7/12,1,0) -> 1 | O3: =IF(F3>8/12,1,0) -> 1 | P3: =IF(F3>9/12,1,0) -> 1 | Q3: =IF(F3>10/12,1,0) -> 1 | R3: =IF(F3>11/12,1,0) -> 1 | S3: =종합!BQ8 -> 2025.4.29
B4: =종합!I4 -> deepseekr1 | C4: =종합!I5 -> 70 | D4: =종합!I6 -> Wrtn | E4: =종합!I7 -> R | F4: =종합!I21 -> 1 | G4: =IF(F4>0/12,1,0) -> 1 | H4: =IF(F4>1/12,1,0) -> 1 | I4: =IF(F4>2/12,1,0) -> 1 | J4: =IF(F4>3/12,1,0) -> 1 | K4: =IF(F4>4/12,1,0) -> 1 | L4: =IF(F4>5/12,1,0) -> 1 | M4: =IF(F4>6/12,1,0) -> 1 | N4: =IF(F4>7/12,1,0) -> 1 | O4: =IF(F4>8/12,1,0) -> 1 | P4: =IF(F4>9/12,1,0) -> 1 | Q4: =IF(F4>10/12,1,0) -> 1 | R4: =IF(F4>11/12,1,0) -> 1
B5: =종합!F4 -> o3mini high | E5: =종합!F7 -> R | F5: =종합!F21 -> 1 | G5: =IF(F5>0/12,1,0) -> 1 | H5: =IF(F5>1/12,1,0) -> 1 | I5: =IF(F5>2/12,1,0) -> 1 | J5: =IF(F5>3/12,1,0) -> 1 | K5: =IF(F5>4/12,1,0) -> 1 | L5: =IF(F5>5/12,1,0) -> 1 | M5: =IF(F5>6/12,1,0) -> 1 | N5: =IF(F5>7/12,1,0) -> 1 | O5: =IF(F5>8/12,1,0) -> 1 | P5: =IF(F5>9/12,1,0) -> 1 | Q5: =IF(F5>10/12,1,0) -> 1 | R5: =IF(F5>11/12,1,0) -> 1
B6: =종합!W4 -> grok 3 | C6: =종합!W5 -> 0 | D6: =종합!W6 -> beta | E6: =종합!W7 -> R | F6: =종합!W21 -> 1 | G6: =IF(F6>0/12,1,0) -> 1 | H6: =IF(F6>1/12,1,0) -> 1 | I6: =IF(F6>2/12,1,0) -> 1 | J6: =IF(F6>3/12,1,0) -> 1 | K6: =IF(F6>4/12,1,0) -> 1 | L6: =IF(F6>5/12,1,0) -> 1 | M6: =IF(F6>6/12,1,0) -> 1 | N6: =IF(F6>7/12,1,0) -> 1 | O6: =IF(F6>8/12,1,0) -> 1 | P6: =IF(F6>9/12,1,0) -> 1 | Q6: =IF(F6>10/12,1,0) -> 1 | R6: =IF(F6>11/12,1,0) -> 1
B7: =종합!Y4 -> Claude3.7s | E7: =종합!Y7 -> R | F7: =종합!Y21 -> 1 | G7: =IF(F7>0/12,1,0) -> 1 | H7: =IF(F7>1/12,1,0) -> 1 | I7: =IF(F7>2/12,1,0) -> 1 | J7: =IF(F7>3/12,1,0) -> 1 | K7: =IF(F7>4/12,1,0) -> 1 | L7: =IF(F7>5/12,1,0) -> 1 | M7: =IF(F7>6/12,1,0) -> 1 | N7: =IF(F7>7/12,1,0) -> 1 | O7: =IF(F7>8/12,1,0) -> 1 | P7: =IF(F7>9/12,1,0) -> 1 | Q7: =IF(F7>10/12,1,0) -> 1 | R7: =IF(F7>11/12,1,0) -> 1
B8: =종합!AQ4 -> gemini 2.5 pro exp. | E8: =종합!AQ7 -> R | F8: =종합!AQ21 -> 1 | G8: =IF(F8>0/12,1,0) -> 1 | H8: =IF(F8>1/12,1,0) -> 1 | I8: =IF(F8>2/12,1,0) -> 1 | J8: =IF(F8>3/12,1,0) -> 1 | K8: =IF(F8>4/12,1,0) -> 1 | L8: =IF(F8>5/12,1,0) -> 1 | M8: =IF(F8>6/12,1,0) -> 1 | N8: =IF(F8>7/12,1,0) -> 1 | O8: =IF(F8>8/12,1,0) -> 1 | P8: =IF(F8>9/12,1,0) -> 1 | Q8: =IF(F8>10/12,1,0) -> 1 | R8: =IF(F8>11/12,1,0) -> 1
B9: =종합!BD4 -> o3 | E9: =종합!BD7 -> R | F9: =종합!BD21 -> 1 | G9: =IF(F9>0/12,1,0) -> 1 | H9: =IF(F9>1/12,1,0) -> 1 | I9: =IF(F9>2/12,1,0) -> 1 | J9: =IF(F9>3/12,1,0) -> 1 | K9: =IF(F9>4/12,1,0) -> 1 | L9: =IF(F9>5/12,1,0) -> 1 | M9: =IF(F9>6/12,1,0) -> 1 | N9: =IF(F9>7/12,1,0) -> 1 | O9: =IF(F9>8/12,1,0) -> 1 | P9: =IF(F9>9/12,1,0) -> 1 | Q9: =IF(F9>10/12,1,0) -> 1 | R9: =IF(F9>11/12,1,0) -> 1
B10: =종합!BR4 -> Qwen3 30A3B | C10: =종합!BR5 -> 30 | E10: =종합!BR7 -> R | F10: =종합!BR21 -> 0.91666667 | G10: =IF(F10>0/12,1,0) -> 1 | H10: =IF(F10>1/12,1,0) -> 1 | I10: =IF(F10>2/12,1,0) -> 1 | J10: =IF(F10>3/12,1,0) -> 1 | K10: =IF(F10>4/12,1,0) -> 1 | L10: =IF(F10>5/12,1,0) -> 1 | M10: =IF(F10>6/12,1,0) -> 1 | N10: =IF(F10>7/12,1,0) -> 1 | O10: =IF(F10>8/12,1,0) -> 1 | P10: =IF(F10>9/12,1,0) -> 1 | Q10: =IF(F10>10/12,1,0) -> 1 | R10: =IF(F10>11/12,1,0) -> 0 | S10: =종합!BR8 -> 2025.4.29
B11: =종합!BE4 -> o4 mini | E11: =종합!BE7 -> R | F11: =종합!BE21 -> 0.91666667 | G11: =IF(F11>0/12,1,0) -> 1 | H11: =IF(F11>1/12,1,0) -> 1 | I11: =IF(F11>2/12,1,0) -> 1 | J11: =IF(F11>3/12,1,0) -> 1 | K11: =IF(F11>4/12,1,0) -> 1 | L11: =IF(F11>5/12,1,0) -> 1 | M11: =IF(F11>6/12,1,0) -> 1 | N11: =IF(F11>7/12,1,0) -> 1 | O11: =IF(F11>8/12,1,0) -> 1 | P11: =IF(F11>9/12,1,0) -> 1 | Q11: =IF(F11>10/12,1,0) -> 1 | R11: =IF(F11>11/12,1,0) -> 0
B12: =종합!BG4 -> gemini 2.5 Flash | E12: =종합!BG7 -> R | F12: =종합!BG21 -> 0.91666667 | G12: =IF(F12>0/12,1,0) -> 1 | H12: =IF(F12>1/12,1,0) -> 1 | I12: =IF(F12>2/12,1,0) -> 1 | J12: =IF(F12>3/12,1,0) -> 1 | K12: =IF(F12>4/12,1,0) -> 1 | L12: =IF(F12>5/12,1,0) -> 1 | M12: =IF(F12>6/12,1,0) -> 1 | N12: =IF(F12>7/12,1,0) -> 1 | O12: =IF(F12>8/12,1,0) -> 1 | P12: =IF(F12>9/12,1,0) -> 1 | Q12: =IF(F12>10/12,1,0) -> 1 | R12: =IF(F12>11/12,1,0) -> 0
B13: =종합!BI4 -> Grok 3 mini | D13: =종합!BI6 -> API / JN | E13: =종합!BI7 -> R | F13: =종합!BI21 -> 0.91666667 | G13: =IF(F13>0/12,1,0) -> 1 | H13: =IF(F13>1/12,1,0) -> 1 | I13: =IF(F13>2/12,1,0) -> 1 | J13: =IF(F13>3/12,1,0) -> 1 | K13: =IF(F13>4/12,1,0) -> 1 | L13: =IF(F13>5/12,1,0) -> 1 | M13: =IF(F13>6/12,1,0) -> 1 | N13: =IF(F13>7/12,1,0) -> 1 | O13: =IF(F13>8/12,1,0) -> 1 | P13: =IF(F13>9/12,1,0) -> 1 | Q13: =IF(F13>10/12,1,0) -> 1 | R13: =IF(F13>11/12,1,0) -> 0
B14: =종합!V4 -> grok 3 | C14: =종합!V5 -> 0 | D14: =종합!V6 -> lmarena | E14: =종합!L7 -> 0 | F14: =종합!V21 -> 0.91666667 | G14: =IF(F14>0/12,1,0) -> 1 | H14: =IF(F14>1/12,1,0) -> 1 | I14: =IF(F14>2/12,1,0) -> 1 | J14: =IF(F14>3/12,1,0) -> 1 | K14: =IF(F14>4/12,1,0) -> 1 | L14: =IF(F14>5/12,1,0) -> 1 | M14: =IF(F14>6/12,1,0) -> 1 | N14: =IF(F14>7/12,1,0) -> 1 | O14: =IF(F14>8/12,1,0) -> 1 | P14: =IF(F14>9/12,1,0) -> 1 | Q14: =IF(F14>10/12,1,0) -> 1 | R14: =IF(F14>11/12,1,0) -> 0
B15: =종합!K4 -> gemini2pro | E15: =종합!K7 -> 0 | F15: =종합!K21 -> 0.91666667 | G15: =IF(F15>0/12,1,0) -> 1 | H15: =IF(F15>1/12,1,0) -> 1 | I15: =IF(F15>2/12,1,0) -> 1 | J15: =IF(F15>3/12,1,0) -> 1 | K15: =IF(F15>4/12,1,0) -> 1 | L15: =IF(F15>5/12,1,0) -> 1 | M15: =IF(F15>6/12,1,0) -> 1 | N15: =IF(F15>7/12,1,0) -> 1 | O15: =IF(F15>8/12,1,0) -> 1 | P15: =IF(F15>9/12,1,0) -> 1 | Q15: =IF(F15>10/12,1,0) -> 1 | R15: =IF(F15>11/12,1,0) -> 0
B16: =종합!X4 -> Claude 3.5s | C16: =종합!X5 -> 0 | D16: =종합!X6 -> 0 | F16: =종합!X21 -> 0.91666667 | G16: =IF(F16>0/12,1,0) -> 1 | H16: =IF(F16>1/12,1,0) -> 1 | I16: =IF(F16>2/12,1,0) -> 1 | J16: =IF(F16>3/12,1,0) -> 1 | K16: =IF(F16>4/12,1,0) -> 1 | L16: =IF(F16>5/12,1,0) -> 1 | M16: =IF(F16>6/12,1,0) -> 1 | N16: =IF(F16>7/12,1,0) -> 1 | O16: =IF(F16>8/12,1,0) -> 1 | P16: =IF(F16>9/12,1,0) -> 1 | Q16: =IF(F16>10/12,1,0) -> 1 | R16: =IF(F16>11/12,1,0) -> 0
B17: =종합!AC4 -> ChatGPT4.5 | C17: =종합!AC5 -> 0 | D17: =종합!AC6 -> 0 | E17: =종합!AC7 -> 0 | F17: =종합!AC21 -> 0.91666667 | G17: =IF(F17>0/12,1,0) -> 1 | H17: =IF(F17>1/12,1,0) -> 1 | I17: =IF(F17>2/12,1,0) -> 1 | J17: =IF(F17>3/12,1,0) -> 1 | K17: =IF(F17>4/12,1,0) -> 1 | L17: =IF(F17>5/12,1,0) -> 1 | M17: =IF(F17>6/12,1,0) -> 1 | N17: =IF(F17>7/12,1,0) -> 1 | O17: =IF(F17>8/12,1,0) -> 1 | P17: =IF(F17>9/12,1,0) -> 1 | Q17: =IF(F17>10/12,1,0) -> 1 | R17: =IF(F17>11/12,1,0) -> 0
B18: =종합!AT4 -> Quasar Alpha | D18: =종합!AT6 -> OpenRouter | F18: =종합!AT21 -> 0.91666667 | G18: =IF(F18>0/12,1,0) -> 1 | H18: =IF(F18>1/12,1,0) -> 1 | I18: =IF(F18>2/12,1,0) -> 1 | J18: =IF(F18>3/12,1,0) -> 1 | K18: =IF(F18>4/12,1,0) -> 1 | L18: =IF(F18>5/12,1,0) -> 1 | M18: =IF(F18>6/12,1,0) -> 1 | N18: =IF(F18>7/12,1,0) -> 1 | O18: =IF(F18>8/12,1,0) -> 1 | P18: =IF(F18>9/12,1,0) -> 1 | Q18: =IF(F18>10/12,1,0) -> 1 | R18: =IF(F18>11/12,1,0) -> 0
B19: =종합!BB4 -> GPT 4.1 mini | D19: =종합!BB6 -> Playground | F19: =종합!BB21 -> 0.91666667 | G19: =IF(F19>0/12,1,0) -> 1 | H19: =IF(F19>1/12,1,0) -> 1 | I19: =IF(F19>2/12,1,0) -> 1 | J19: =IF(F19>3/12,1,0) -> 1 | K19: =IF(F19>4/12,1,0) -> 1 | L19: =IF(F19>5/12,1,0) -> 1 | M19: =IF(F19>6/12,1,0) -> 1 | N19: =IF(F19>7/12,1,0) -> 1 | O19: =IF(F19>8/12,1,0) -> 1 | P19: =IF(F19>9/12,1,0) -> 1 | Q19: =IF(F19>10/12,1,0) -> 1 | R19: =IF(F19>11/12,1,0) -> 0
B20: =종합!D4 -> deepseekr1 | C20: =종합!D5 -> 70 | D20: =종합!D6 -> groq | E20: =종합!D7 -> R | F20: =종합!D21 -> 0.875 | G20: =IF(F20>0/12,1,0) -> 1 | H20: =IF(F20>1/12,1,0) -> 1 | I20: =IF(F20>2/12,1,0) -> 1 | J20: =IF(F20>3/12,1,0) -> 1 | K20: =IF(F20>4/12,1,0) -> 1 | L20: =IF(F20>5/12,1,0) -> 1 | M20: =IF(F20>6/12,1,0) -> 1 | N20: =IF(F20>7/12,1,0) -> 1 | O20: =IF(F20>8/12,1,0) -> 1 | P20: =IF(F20>9/12,1,0) -> 1 | Q20: =IF(F20>10/12,1,0) -> 1 | R20: =IF(F20>11/12,1,0) -> 0
B21: =종합!AS4 -> Llama4 Maverick | C21: =종합!AS5 -> 400 | D21: =종합!AS6 -> OpenRouter | F21: =종합!AS21 -> 0.83333333 | G21: =IF(F21>0/12,1,0) -> 1 | H21: =IF(F21>1/12,1,0) -> 1 | I21: =IF(F21>2/12,1,0) -> 1 | J21: =IF(F21>3/12,1,0) -> 1 | K21: =IF(F21>4/12,1,0) -> 1 | L21: =IF(F21>5/12,1,0) -> 1 | M21: =IF(F21>6/12,1,0) -> 1 | N21: =IF(F21>7/12,1,0) -> 1 | O21: =IF(F21>8/12,1,0) -> 1 | P21: =IF(F21>9/12,1,0) -> 1 | Q21: =IF(F21>10/12,1,0) -> 0 | R21: =IF(F21>11/12,1,0) -> 0
B22: =종합!BS4 -> Qwen3 32 | C22: =종합!BS5 -> 32 | D22: =종합!BS6 -> OpenRouter | E22: =종합!BS7 -> R | F22: =종합!BS21 -> 0.83333333 | G22: =IF(F22>0/12,1,0) -> 1 | H22: =IF(F22>1/12,1,0) -> 1 | I22: =IF(F22>2/12,1,0) -> 1 | J22: =IF(F22>3/12,1,0) -> 1 | K22: =IF(F22>4/12,1,0) -> 1 | L22: =IF(F22>5/12,1,0) -> 1 | M22: =IF(F22>6/12,1,0) -> 1 | N22: =IF(F22>7/12,1,0) -> 1 | O22: =IF(F22>8/12,1,0) -> 1 | P22: =IF(F22>9/12,1,0) -> 1 | Q22: =IF(F22>10/12,1,0) -> 0 | R22: =IF(F22>11/12,1,0) -> 0 | S22: =종합!BS8 -> 2025.4.30
B23: =종합!BT4 -> Qwen3 14 | C23: =종합!BT5 -> 14 | D23: =종합!BT6 -> OpenRouter | E23: =종합!BT7 -> R | F23: =종합!BT21 -> 0.83333333 | G23: =IF(F23>0/12,1,0) -> 1 | H23: =IF(F23>1/12,1,0) -> 1 | I23: =IF(F23>2/12,1,0) -> 1 | J23: =IF(F23>3/12,1,0) -> 1 | K23: =IF(F23>4/12,1,0) -> 1 | L23: =IF(F23>5/12,1,0) -> 1 | M23: =IF(F23>6/12,1,0) -> 1 | N23: =IF(F23>7/12,1,0) -> 1 | O23: =IF(F23>8/12,1,0) -> 1 | P23: =IF(F23>9/12,1,0) -> 1 | Q23: =IF(F23>10/12,1,0) -> 0 | R23: =IF(F23>11/12,1,0) -> 0 | S23: =종합!BT8 -> 2025.4.30
B24: =종합!BU4 -> Qwen3 8 | C24: =종합!BU5 -> 8 | D24: =종합!BU6 -> OpenRouter | E24: =종합!BU7 -> R | F24: =종합!BU21 -> 0.83333333 | G24: =IF(F24>0/12,1,0) -> 1 | H24: =IF(F24>1/12,1,0) -> 1 | I24: =IF(F24>2/12,1,0) -> 1 | J24: =IF(F24>3/12,1,0) -> 1 | K24: =IF(F24>4/12,1,0) -> 1 | L24: =IF(F24>5/12,1,0) -> 1 | M24: =IF(F24>6/12,1,0) -> 1 | N24: =IF(F24>7/12,1,0) -> 1 | O24: =IF(F24>8/12,1,0) -> 1 | P24: =IF(F24>9/12,1,0) -> 1 | Q24: =IF(F24>10/12,1,0) -> 0 | R24: =IF(F24>11/12,1,0) -> 0 | S24: =종합!BU8 -> 2025.4.30
B25: =종합!Z4 -> Qwen2.5Max | E25: =종합!Z7 -> R | F25: =종합!Z21 -> 0.83333333 | G25: =IF(F25>0/12,1,0) -> 1 | H25: =IF(F25>1/12,1,0) -> 1 | I25: =IF(F25>2/12,1,0) -> 1 | J25: =IF(F25>3/12,1,0) -> 1 | K25: =IF(F25>4/12,1,0) -> 1 | L25: =IF(F25>5/12,1,0) -> 1 | M25: =IF(F25>6/12,1,0) -> 1 | N25: =IF(F25>7/12,1,0) -> 1 | O25: =IF(F25>8/12,1,0) -> 1 | P25: =IF(F25>9/12,1,0) -> 1 | Q25: =IF(F25>10/12,1,0) -> 0 | R25: =IF(F25>11/12,1,0) -> 0
B26: =종합!P4 -> kimi 1.5 | E26: =종합!P7 -> R | F26: =종합!P21 -> 0.83333333 | G26: =IF(F26>0/12,1,0) -> 1 | H26: =IF(F26>1/12,1,0) -> 1 | I26: =IF(F26>2/12,1,0) -> 1 | J26: =IF(F26>3/12,1,0) -> 1 | K26: =IF(F26>4/12,1,0) -> 1 | L26: =IF(F26>5/12,1,0) -> 1 | M26: =IF(F26>6/12,1,0) -> 1 | N26: =IF(F26>7/12,1,0) -> 1 | O26: =IF(F26>8/12,1,0) -> 1 | P26: =IF(F26>9/12,1,0) -> 1 | Q26: =IF(F26>10/12,1,0) -> 0 | R26: =IF(F26>11/12,1,0) -> 0
B27: =종합!AN4 -> Ernie x1 | E27: =종합!AN7 -> R | F27: =종합!AN21 -> 0.83333333 | G27: =IF(F27>0/12,1,0) -> 1 | H27: =IF(F27>1/12,1,0) -> 1 | I27: =IF(F27>2/12,1,0) -> 1 | J27: =IF(F27>3/12,1,0) -> 1 | K27: =IF(F27>4/12,1,0) -> 1 | L27: =IF(F27>5/12,1,0) -> 1 | M27: =IF(F27>6/12,1,0) -> 1 | N27: =IF(F27>7/12,1,0) -> 1 | O27: =IF(F27>8/12,1,0) -> 1 | P27: =IF(F27>9/12,1,0) -> 1 | Q27: =IF(F27>10/12,1,0) -> 0 | R27: =IF(F27>11/12,1,0) -> 0
B28: =종합!BF4 -> o4 mini high | E28: =종합!BF7 -> R | F28: =종합!BF21 -> 0.83333333 | G28: =IF(F28>0/12,1,0) -> 1 | H28: =IF(F28>1/12,1,0) -> 1 | I28: =IF(F28>2/12,1,0) -> 1 | J28: =IF(F28>3/12,1,0) -> 1 | K28: =IF(F28>4/12,1,0) -> 1 | L28: =IF(F28>5/12,1,0) -> 1 | M28: =IF(F28>6/12,1,0) -> 1 | N28: =IF(F28>7/12,1,0) -> 1 | O28: =IF(F28>8/12,1,0) -> 1 | P28: =IF(F28>9/12,1,0) -> 1 | Q28: =IF(F28>10/12,1,0) -> 0 | R28: =IF(F28>11/12,1,0) -> 0
B29: =종합!AP4 -> Deepseekv30324 | D29: =종합!AP6 -> OpenRouter | F29: =종합!AP21 -> 0.83333333 | G29: =IF(F29>0/12,1,0) -> 1 | H29: =IF(F29>1/12,1,0) -> 1 | I29: =IF(F29>2/12,1,0) -> 1 | J29: =IF(F29>3/12,1,0) -> 1 | K29: =IF(F29>4/12,1,0) -> 1 | L29: =IF(F29>5/12,1,0) -> 1 | M29: =IF(F29>6/12,1,0) -> 1 | N29: =IF(F29>7/12,1,0) -> 1 | O29: =IF(F29>8/12,1,0) -> 1 | P29: =IF(F29>9/12,1,0) -> 1 | Q29: =IF(F29>10/12,1,0) -> 0 | R29: =IF(F29>11/12,1,0) -> 0
B30: =종합!BC4 -> GPT 4.1 | D30: =종합!BC6 -> Playground | F30: =종합!BC21 -> 0.83333333 | G30: =IF(F30>0/12,1,0) -> 1 | H30: =IF(F30>1/12,1,0) -> 1 | I30: =IF(F30>2/12,1,0) -> 1 | J30: =IF(F30>3/12,1,0) -> 1 | K30: =IF(F30>4/12,1,0) -> 1 | L30: =IF(F30>5/12,1,0) -> 1 | M30: =IF(F30>6/12,1,0) -> 1 | N30: =IF(F30>7/12,1,0) -> 1 | O30: =IF(F30>8/12,1,0) -> 1 | P30: =IF(F30>9/12,1,0) -> 1 | Q30: =IF(F30>10/12,1,0) -> 0 | R30: =IF(F30>11/12,1,0) -> 0
B31: =종합!BN4 -> Ernie X1 Turbo | E31: =종합!BN7 -> R | F31: =종합!BN21 -> 0.83333333 | G31: =IF(F31>0/12,1,0) -> 1 | H31: =IF(F31>1/12,1,0) -> 1 | I31: =IF(F31>2/12,1,0) -> 1 | J31: =IF(F31>3/12,1,0) -> 1 | K31: =IF(F31>4/12,1,0) -> 1 | L31: =IF(F31>5/12,1,0) -> 1 | M31: =IF(F31>6/12,1,0) -> 1 | N31: =IF(F31>7/12,1,0) -> 1 | O31: =IF(F31>8/12,1,0) -> 1 | P31: =IF(F31>9/12,1,0) -> 1 | Q31: =IF(F31>10/12,1,0) -> 0 | R31: =IF(F31>11/12,1,0) -> 0 | S31: =종합!BN8 -> 2025.4.25
B32: =종합!E4 -> Qwen 2.5max | E32: =종합!E7 -> 0 | F32: =종합!E21 -> 0.8 | G32: =IF(F32>0/12,1,0) -> 1 | H32: =IF(F32>1/12,1,0) -> 1 | I32: =IF(F32>2/12,1,0) -> 1 | J32: =IF(F32>3/12,1,0) -> 1 | K32: =IF(F32>4/12,1,0) -> 1 | L32: =IF(F32>5/12,1,0) -> 1 | M32: =IF(F32>6/12,1,0) -> 1 | N32: =IF(F32>7/12,1,0) -> 1 | O32: =IF(F32>8/12,1,0) -> 1 | P32: =IF(F32>9/12,1,0) -> 1 | Q32: =IF(F32>10/12,1,0) -> 0 | R32: =IF(F32>11/12,1,0) -> 0
B33: =종합!G4 -> Tulu3 | C33: =종합!G5 -> 405 | D33: =종합!G6 -> 0 | E33: =종합!G7 -> 0 | F33: =종합!G21 -> 0.75 | G33: =IF(F33>0/12,1,0) -> 1 | H33: =IF(F33>1/12,1,0) -> 1 | I33: =IF(F33>2/12,1,0) -> 1 | J33: =IF(F33>3/12,1,0) -> 1 | K33: =IF(F33>4/12,1,0) -> 1 | L33: =IF(F33>5/12,1,0) -> 1 | M33: =IF(F33>6/12,1,0) -> 1 | N33: =IF(F33>7/12,1,0) -> 1 | O33: =IF(F33>8/12,1,0) -> 1 | P33: =IF(F33>9/12,1,0) -> 0 | Q33: =IF(F33>10/12,1,0) -> 0 | R33: =IF(F33>11/12,1,0) -> 0
B34: =종합!AF4 -> QwQ-32b | C34: =종합!AF5 -> 32 | D34: =종합!AF6 -> 0 | E34: =종합!AF7 -> R | F34: =종합!AF21 -> 0.75 | G34: =IF(F34>0/12,1,0) -> 1 | H34: =IF(F34>1/12,1,0) -> 1 | I34: =IF(F34>2/12,1,0) -> 1 | J34: =IF(F34>3/12,1,0) -> 1 | K34: =IF(F34>4/12,1,0) -> 1 | L34: =IF(F34>5/12,1,0) -> 1 | M34: =IF(F34>6/12,1,0) -> 1 | N34: =IF(F34>7/12,1,0) -> 1 | O34: =IF(F34>8/12,1,0) -> 1 | P34: =IF(F34>9/12,1,0) -> 0 | Q34: =IF(F34>10/12,1,0) -> 0 | R34: =IF(F34>11/12,1,0) -> 0
B35: =종합!J4 -> gemini2flash | E35: =종합!J7 -> R | F35: =종합!J21 -> 0.75 | G35: =IF(F35>0/12,1,0) -> 1 | H35: =IF(F35>1/12,1,0) -> 1 | I35: =IF(F35>2/12,1,0) -> 1 | J35: =IF(F35>3/12,1,0) -> 1 | K35: =IF(F35>4/12,1,0) -> 1 | L35: =IF(F35>5/12,1,0) -> 1 | M35: =IF(F35>6/12,1,0) -> 1 | N35: =IF(F35>7/12,1,0) -> 1 | O35: =IF(F35>8/12,1,0) -> 1 | P35: =IF(F35>9/12,1,0) -> 0 | Q35: =IF(F35>10/12,1,0) -> 0 | R35: =IF(F35>11/12,1,0) -> 0
B36: =종합!AO4 -> Hunyuan T1 | E36: =종합!AO7 -> R | F36: =종합!AO21 -> 0.75 | G36: =IF(F36>0/12,1,0) -> 1 | H36: =IF(F36>1/12,1,0) -> 1 | I36: =IF(F36>2/12,1,0) -> 1 | J36: =IF(F36>3/12,1,0) -> 1 | K36: =IF(F36>4/12,1,0) -> 1 | L36: =IF(F36>5/12,1,0) -> 1 | M36: =IF(F36>6/12,1,0) -> 1 | N36: =IF(F36>7/12,1,0) -> 1 | O36: =IF(F36>8/12,1,0) -> 1 | P36: =IF(F36>9/12,1,0) -> 0 | Q36: =IF(F36>10/12,1,0) -> 0 | R36: =IF(F36>11/12,1,0) -> 0
B37: =종합!N4 -> Mistral | C37: =종합!N5 -> 0 | D37: =종합!N6 -> le chat | E37: =종합!N7 -> 0 | F37: =종합!N21 -> 0.75 | G37: =IF(F37>0/12,1,0) -> 1 | H37: =IF(F37>1/12,1,0) -> 1 | I37: =IF(F37>2/12,1,0) -> 1 | J37: =IF(F37>3/12,1,0) -> 1 | K37: =IF(F37>4/12,1,0) -> 1 | L37: =IF(F37>5/12,1,0) -> 1 | M37: =IF(F37>6/12,1,0) -> 1 | N37: =IF(F37>7/12,1,0) -> 1 | O37: =IF(F37>8/12,1,0) -> 1 | P37: =IF(F37>9/12,1,0) -> 0 | Q37: =IF(F37>10/12,1,0) -> 0 | R37: =IF(F37>11/12,1,0) -> 0
B38: =종합!AX4 -> Optimus Alpha | D38: =종합!AX6 -> OpenRouter | F38: =종합!AX21 -> 0.75 | G38: =IF(F38>0/12,1,0) -> 1 | H38: =IF(F38>1/12,1,0) -> 1 | I38: =IF(F38>2/12,1,0) -> 1 | J38: =IF(F38>3/12,1,0) -> 1 | K38: =IF(F38>4/12,1,0) -> 1 | L38: =IF(F38>5/12,1,0) -> 1 | M38: =IF(F38>6/12,1,0) -> 1 | N38: =IF(F38>7/12,1,0) -> 1 | O38: =IF(F38>8/12,1,0) -> 1 | P38: =IF(F38>9/12,1,0) -> 0 | Q38: =IF(F38>10/12,1,0) -> 0 | R38: =IF(F38>11/12,1,0) -> 0
B39: =종합!AH4 -> Gemma3 | C39: =종합!AH5 -> 27 | D39: =종합!AH6 -> AIstudio | F39: =종합!AH21 -> 0.66666667 | G39: =IF(F39>0/12,1,0) -> 1 | H39: =IF(F39>1/12,1,0) -> 1 | I39: =IF(F39>2/12,1,0) -> 1 | J39: =IF(F39>3/12,1,0) -> 1 | K39: =IF(F39>4/12,1,0) -> 1 | L39: =IF(F39>5/12,1,0) -> 1 | M39: =IF(F39>6/12,1,0) -> 1 | N39: =IF(F39>7/12,1,0) -> 1 | O39: =IF(F39>8/12,1,0) -> 0 | P39: =IF(F39>9/12,1,0) -> 0 | Q39: =IF(F39>10/12,1,0) -> 0 | R39: =IF(F39>11/12,1,0) -> 0
B40: =종합!BP4 -> DeepCoder | C40: =종합!BP5 -> 14 | D40: =종합!BP6 -> OpenRouter | E40: =종합!BP7 -> R | F40: =종합!BP21 -> 0.66666667 | G40: =IF(F40>0/12,1,0) -> 1 | H40: =IF(F40>1/12,1,0) -> 1 | I40: =IF(F40>2/12,1,0) -> 1 | J40: =IF(F40>3/12,1,0) -> 1 | K40: =IF(F40>4/12,1,0) -> 1 | L40: =IF(F40>5/12,1,0) -> 1 | M40: =IF(F40>6/12,1,0) -> 1 | N40: =IF(F40>7/12,1,0) -> 1 | O40: =IF(F40>8/12,1,0) -> 0 | P40: =IF(F40>9/12,1,0) -> 0 | Q40: =IF(F40>10/12,1,0) -> 0 | R40: =IF(F40>11/12,1,0) -> 0 | S40: =종합!BP8 -> 2025.4.27
B41: =종합!AW4 -> Zyphra ZR1 | C41: =종합!AW5 -> 1.5 | D41: =종합!AW6 -> LMStudio | E41: =종합!AW7 -> R | F41: =종합!AW21 -> 0.66666667 | G41: =IF(F41>0/12,1,0) -> 1 | H41: =IF(F41>1/12,1,0) -> 1 | I41: =IF(F41>2/12,1,0) -> 1 | J41: =IF(F41>3/12,1,0) -> 1 | K41: =IF(F41>4/12,1,0) -> 1 | L41: =IF(F41>5/12,1,0) -> 1 | M41: =IF(F41>6/12,1,0) -> 1 | N41: =IF(F41>7/12,1,0) -> 1 | O41: =IF(F41>8/12,1,0) -> 0 | P41: =IF(F41>9/12,1,0) -> 0 | Q41: =IF(F41>10/12,1,0) -> 0 | R41: =IF(F41>11/12,1,0) -> 0
...

Sheet 모델기능
A3: 모델명 | B3: 추론 | C3: 멀티모달 | D3: 검색 | E3: canvas | F3: code | G3: code | H3: 이미지 | I3: 파일첨부 | P3: URL | Q3: ETC
F4: interpreter | G4: preview | H4: 생성 | I4: img | J4: pdf | K4: doc | L4: xlsx | M4: ppt | N4: g.docs | O4: txt
A5: kimi 1.5 | B5: TRUE | C5: TRUE | D5: TRUE | I5: TRUE | J5: TRUE | K5: TRUE | L5: TRUE | M5: TRUE | O5: TRUE | P5: kimi.ai
A6: Mistral Le chat | C6: TRUE | D6: TRUE | E6: TRUE | F6: TRUE | H6: TRUE | I6: TRUE | J6: TRUE | O6: TRUE | P6: chat.mistral.ai/
A7: claude | C7: TRUE | F7: TRUE | G7: TRUE | I7: TRUE | J7: TRUE | K7: TRUE | N7: TRUE | O7: TRUE | P7: claude.ai
A8: cohere | D8: TRUE | F8: TRUE | J8: TRUE | O8: TRUE | P8: cohere.com/
A9: Reka | B9: TRUE | C9: TRUE | H9: TRUE | I9: TRUE | J9: TRUE | P9: reka.ai | Q9: Space

Sheet 문항
A1: 문제 1 | B1: AABABCABCD 다음에 올 문자열은 무엇입니까? 패턴을 분석하고 설명해주세요. | C1: AABABCABCDABCDE
A2: 문제 2 | B2: 어떤 수에 5를 더하면 그 수의 2배보다 3이 작습니다. 이 수를 x라고 할 때, x의 값을 구하는 방정식을 세우고 풀어보세요. | C2: x + 5 = 2x - 3 8
A3: 문제 3 | B3: 빨강, 파랑, 노랑, 초록, 보라 순서로 색상이 반복되는 패턴이 있습니다. 57번째 색상은 무엇일까요? | C3: 파랑
A4: 문제 4 | B4: 다섯 명이 사과를 먹고 있습니다. A는 B보다 먼저 먹었지만 C보다는 늦게 먹었습니다. D는 E보다 만저 먹었지만 B보다는 늦게 먹었습니다. 사과를 먹은 순서는 어떻게 될까요? | C4: C, A, B, D, E
A5: 문제 5 | B5: 세 명이 일렬로 서 있습니다. 가장 뒤에 있는 사람은 앞의 두 사람의 모자를 볼 수 있고, 중간에 있는 사람은 맨 앞 사람의 모자를 볼 수 있습니다. 맨 앞 사람은 아무도 볼 수 없습니다. 그들은 검은 모자 3개와 흰 모자 2개 중에서 모자를 쓰게 됩니다. 가장 뒷사람부터 차례로 질물은 했습니다. 가장 뒤에 있는 사람에게 자신의 모자 색을 아는지 물었더니 모른다고 합니다. 중간 사람도 모른다고 합니다. 그런데 맨 앞사람이 자산의 모자 색을 안다고 합니다. 맨 앞 사람은 어떻게 알 수 있었을 까요? | C5: 마지막 사람이 모르는 이유: 앞사람들의 모자 색이 검은색, 흰색이 있음. 중간 사람이 모르는 이유는 앞사람이 흰색일 경우에만 검은색임 앞사람은 뒤 사람들의 대답을 종합하여 검은색 모자임을 유추할 수 있음 검은색
A6: 문제 6 | B6: 26개의 똑같이 생긴 동전 중 하나는 다른 동전보다 가벼운 가짜 동전입니다. 눈금이 없는 양팔저울만 사용해서 이 가짜 동전을 찾아내려면, 최소 몇 번 저울질을 해야 할까요? | C6: 3번
A7: 문제 7 | B7: 현재 아버지의 나이는 아들 나이의 4배입니다. 5년 전에는 아버지의 나이가 아들 나이의 5배였습니다. 현재 아버지의 나이는 몇 살일까요? | C7: 4x - 5 = 5(x -5) 80세
A8: 문제 8 | B8: 세 명의 용의자 A, B, C 중 한 명이 범인입니다. A는 "내가 범인이 아니다"라고 말합니다. B는 "A가 범인이다."라고 말합니다. C는 "B가 범인이 아니다"라고 말합니다. 만약 이들 중 단 한명만 진실을 말하고 있다면, 누가 범인일까요? | C8: B
A9: 문제 9 | B9: 두 개의 8면체 주사위는 각각 1부터 8까지 번호가 매겨진 면을 가지고 있습니다. 주사위를 굴리면, 각 면이 위로 올 확률은 동일합니다. 두 숫자의 곱이 그들의 합보다 클 확률은 얼마입니까? 답을 기약분수로 표현하세요 | C9: 3/4
A10: 문제 10 | B10: 너는 civil engineer야. fck=35MPa, fy=400MPa, b=1000mm, h=800mm, cover(표면~철근중심)=80mm, 강도감소계수=0.85, Mu=1000kN.m일 때 USD 설계법으로 필요철근량을 구하라. | C10: 4255mm^2
A11: 문제 11 | B11: 사용자로부터 2차 방정식의 a,b,c를 입력받은 후 근을 구하는 과정을 보여주는 웹 앱을 만들어. HTML에 js를 포함시켜. Mathjax를 사용하여 모든 수식을 렌더링해. 근을 보여주는 부분의 아래에 2차방정식 그래프를 그리는 부분을 추가해줘. 그래프는 chart.js를 적용해. 그래프에 두 근을 표시하고, 두 근이 보이도록 x축의 범위를 적절하게 조정해줘. | C11: html 코드 a, b, c
A12: 문제 12 | B12: i-beam의 제원을 사용자로부터 입력 받아서 그리는 웹앱을 만들어줘. i-beam의 단면적과 단면적을 구하는 과정을 보여주는 기능도 추가해. html에 js를 포함해줘. 입력받을 제원은 상부 및 하부 플랜지 폭과 두께, 웹의 높이와 두께. 단위는 mm. 제원의 초기값으로 아래의 값을 적용해. 상부 및 하부 플랜지: 폭 300mm, 두께 15mm 웹: 높이 270mm, 두께 10mm. | C12: 상부 플랜지 폭: 300 상부 플랜지 두께: 15 하부 플랜지 폭: 300 하부 플랜지 두께: 15 웹 높이: 270 웹 두께: 10 11700mm^2
